Error running data_generator.py: Command '['python', 'data_generator.py']' returned non-zero exit status 2.
Test case # 1 